Workbook

Sheet Sheet1
A1: =_xlfn.DISPIMG("ID_E5F16E92F4164DD3808EB5806117DC00",1) -> =DISPIMG("ID_E5F16E92F4164DD3808EB5806117DC00",1) | D1: PT. VANTSING INTERNATIONAL GROUP
D3: Address 地址： Soldays X Lesso Jl. Raya Daan Mogot No 1 RT 06 Rw 02, Samping Rusun Polri RQR9 H7P RT06RW02, North Kedoya Kebonjeruk, West Jakarta, DKI Jakarta, 11520.
A4: 万鼎 | D4: Contact Person联系人：Rubi Contact Number / 联系电话 ： +62 878-2061-8709 Mail：vantsing@vtintl.id
A5: 报价单 PENAWARAN HARGA
A6: NO | B6: Nama Permintaan | C6: Spesifikasi Permintaan | D6: Satuan | E6: QTY | F6: Product number | G6: Nama Penawaran | H6: Nama Indonesia | I6: Spesifikasi Penawaran | J6: Satuan | K6: QTY | L6: Brand | M6: Harga | N6: Total Harga | O6: Catatan
A7: 序号 | B7: 询价名称 | C7: 询价规格 | D7: 单位 | E7: 数量 | F7: 产品编号 | G7: 报价名称 | H7: 印尼名称 | I7: 报价规格 | J7: 单位 | K7: 数量 | L7: 品牌 | M7: 单价 | N7: 总额 | O7: 备注
A8: 1 | B8: 排水管 | C8: 150 | D8: 根 | E8: 7 | F8: 8020010044 | G8: =VLOOKUP(F8,'[1]国标管件 1'!$C:$I,2,FALSE) -> 建筑排水用PVC-U管(A)白色 dn160 4M | H8: =VLOOKUP(F8,'[1]国标管件 1'!$C:$I,3,FALSE) -> PVC-U Drain Pipe(A) dn160 4M - LESSO | I8: dn160 | J8: 4M/根 | K8: =E8 -> 7 | L8: 联塑 | M8: =VLOOKUP(F8,'[1]国标管件 1'!$C:$I,7,FALSE) -> 292456 | N8: =M8*K8 -> 2047192 | O8: 现货
A9: 2 | B9: 排水管 | C9: 150直通 | D9: 个 | E9: 6 | F9: 8020020748 | G9: =VLOOKUP(F9,'[1]国标管件 1'!$C:$I,2,FALSE) -> 直通(管)PVC-U排水配件白色dn160 | H9: =VLOOKUP(F9,'[1]国标管件 1'!$C:$I,3,FALSE) -> Straight-through (Pipe Clamp) PVC-U drainage fitting white dn160 - LESSO | I9: dn160 | J9: =D9 -> 个 | K9: =E9 -> 6 | L9: 联塑 | M9: =VLOOKUP(F9,'[1]国标管件 1'!$C:$I,7,FALSE) -> 20062 | N9: =M9*K9 -> 120372 | O9: 现货
A10: 3 | B10: 排水管 | C10: 150 三通 | D10: 个 | E10: 1 | F10: 8020020337 | G10: =VLOOKUP(F10,'[1]国标管件 1'!$C:$I,2,FALSE) -> 90°顺水三通(等径三通)PVC-U排水配件白色 dn160 | H10: =VLOOKUP(F10,'[1]国标管件 1'!$C:$I,3,FALSE) -> dn160 Sanitary tee(PVC-U DF) | I10: dn160 | J10: 个 | K10: 1 | L10: 联塑 | M10: =VLOOKUP(F10,'[1]国标管件 1'!$C:$I,7,FALSE) -> 64044 | N10: =M10*K10 -> 64044 | O10: 现货
A11: 4 | B11: 排水管 | C11: 90度弯头 | D11: 个 | E11: 3 | F11: 8020020592 | G11: =VLOOKUP(F11,'[1]国标管件 1'!$C:$I,2,FALSE) -> 90°直角弯头PVC-U排水配件白色 dn160 | I11: dn160 | J11: =D11 -> 个 | K11: =E11 -> 3 | L11: 联塑 | M11: =VLOOKUP(F11,'[1]国标管件 1'!$C:$I,7,FALSE) -> 42570 | N11: =M11*K11 -> 127710 | O11: 现货
A12: 5 | B12: 排水管 | C12: 45度弯头 | D12: 个 | E12: 8 | F12: 8020020558 | G12: =VLOOKUP(F12,'[1]国标管件 1'!$C:$I,2,FALSE) -> 45°弯头PVC-U排水配件白色 dn160 | H12: =VLOOKUP(F12,'[1]国标管件 1'!$C:$I,3,FALSE) -> 45° Elbow (PVC-U DF) dn160 - LESSO | I12: dn160 | J12: =D12 -> 个 | K12: =E12 -> 8 | L12: 联塑 | M12: =VLOOKUP(F12,'[1]国标管件 1'!$C:$I,7,FALSE) -> 32477 | N12: =M12*K12 -> 259816 | O12: 现货
A13: 6 | B13: 排水管 | C13: 150管夹 | D13: 个 | E13: 11 | F13: 8020020182 | G13: =VLOOKUP(F13,'[1]国标管件 1'!$C:$I,2,FALSE) -> PVC管卡(配尖咀螺丝)PVC-U排水配件白色 dn160 | H13: =VLOOKUP(F13,'[1]国标管件 1'!$C:$I,3,FALSE) -> dn160 PVC pipe clamp(TS PVC-U DF) | I13: =_xlfn.DISPIMG("ID_678C06D8FD2743858F179D7FABF1A445",1) -> =DISPIMG("ID_678C06D8FD2743858F179D7FABF1A445",1) | J13: =D13 -> 个 | K13: =E13 -> 11 | L13: 联塑 | M13: =VLOOKUP(F13,'[1]国标管件 1'!$C:$I,7,FALSE) -> 11114 | N13: =M13*K13 -> 122254 | O13: 现货
A14: 7 | B14: 排水管 | C14: 150变110 直通 | D14: 个 | E14: 1 | F14: 8020020049 | G14: =VLOOKUP(F14,'[1]国标管件 1'!$C:$I,2,FALSE) -> 大小头PVC-U排水配件白色 dn160×110 | H14: =VLOOKUP(F14,'[1]国标管件 1'!$C:$I,3,FALSE) -> dn160X110 Reducing bushing(PVC-U DF) -LESSO | I14: =_xlfn.DISPIMG("ID_A0F5DF1EE69948DCA8060B0199DDAFC2",1) -> =DISPIMG("ID_A0F5DF1EE69948DCA8060B0199DDAFC2",1) | J14: =D14 -> 个 | K14: =E14 -> 1 | L14: 联塑 | M14: =VLOOKUP(F14,'[1]国标管件 1'!$C:$I,7,FALSE) -> 15437 | N14: =M14*K14 -> 15437 | O14: 现货
A15: 8 | B15: 排水管 | C15: 110 | D15: 根 | E15: 5 | F15: 8020010018 | G15: =VLOOKUP(F15,'[1]国标管件 1'!$C:$I,2,FALSE) -> 建筑排水用PVC-U管(A)白色 dn110 4M | H15: =VLOOKUP(F15,'[1]国标管件 1'!$C:$I,3,FALSE) -> PVC-U Drain Pipe (A) 4M dn110 - LESSO | I15: dn110 | J15: 4M/根 | K15: =E15 -> 5 | L15: 联塑 | M15: =VLOOKUP(F15,'[1]国标管件 1'!$C:$I,7,FALSE) -> 159042 | N15: =M15*K15 -> 795210 | O15: 现货
A16: 9 | B16: 排水管 | C16: 存水弯，带检修盖110 | D16: 个 | E16: 10 | F16: 8020020240 | G16: =VLOOKUP(F16,'[1]国标管件 1'!$C:$I,2,FALSE) -> P型存水弯(带检查口)PVC-U排水配件白色 dn110 | H16: =VLOOKUP(F16,'[1]国标管件 1'!$C:$I,3,FALSE) -> dn110 P Trap with cleanout(PVC-U DF) -LESSO | I16: =_xlfn.DISPIMG("ID_5324B4CA577F40F79D0854AE95EAC2B3",1) -> =DISPIMG("ID_5324B4CA577F40F79D0854AE95EAC2B3",1) | J16: =D16 -> 个 | K16: =E16 -> 10 | L16: 联塑 | M16: =VLOOKUP(F16,'[1]国标管件 1'!$C:$I,7,FALSE) -> 59845 | N16: =M16*K16 -> 598450 | O16: 现货
A17: 10 | B17: 排水管 | C17: 110斜三通 | D17: 个 | E17: 7 | F17: 8020020405 | G17: =VLOOKUP(F17,'[1]国标管件 1'!$C:$I,2,FALSE) -> 45°斜三通PVC-U排水配件白色 dn110 | H17: =VLOOKUP(F17,'[1]国标管件 1'!$C:$I,3,FALSE) -> dn110 Wye(PVC-U DF) - LESSO | I17: dn110 | J17: =D17 -> 个 | K17: =E17 -> 7 | L17: 联塑 | M17: =VLOOKUP(F17,'[1]国标管件 1'!$C:$I,7,FALSE) -> 34302 | N17: =M17*K17 -> 240114 | O17: 现货
A18: 11 | B18: 排水管 | C18: 110正三通 | D18: 个 | E18: 8 | F18: 8020020349 | G18: =VLOOKUP(F18,'[1]国标管件 1'!$C:$I,2,FALSE) -> 90°顺水三通(等径三通)PVC-U排水配件白色 dn110 | H18: =VLOOKUP(F18,'[1]国标管件 1'!$C:$I,3,FALSE) -> dn110 Sanitary tee(PVC-U DF) -LESSO | I18: dn110 | J18: =D18 -> 个 | K18: =E18 -> 8 | L18: 联塑 | M18: =VLOOKUP(F18,'[1]国标管件 1'!$C:$I,7,FALSE) -> 26274 | N18: =M18*K18 -> 210192 | O18: 现货
A19: 12 | B19: 排水管 | C19: 110直通 | D19: 个 | E19: 10 | F19: 无货
A20: 13 | B20: 排水管 | C20: 90度弯头 | D20: 个 | E20: 8 | F20: 8020020588 | G20: =VLOOKUP(F20,'[1]国标管件 1'!$C:$I,2,FALSE) -> 90°直角弯头PVC-U排水配件白色 dn110 | H20: =VLOOKUP(F20,'[1]国标管件 1'!$C:$I,3,FALSE) -> elbow dia 90 110mm - LESSO | I20: dn110 | J20: =D20 -> 个 | K20: =E20 -> 8 | L20: 联塑 | M20: =VLOOKUP(F20,'[1]国标管件 1'!$C:$I,7,FALSE) -> 19340 | N20: =M20*K20 -> 154720 | O20: 现货
A21: 14 | B21: 排水管 | C21: 90度弯头，带检修口 | D21: 个 | E21: 2 | F21: 8020020639 | G21: =VLOOKUP(F21,'[1]国标管件 1'!$C:$I,2,FALSE) -> 90°弯头(带检查口)PVC-U排水配件白色 dn110 | H21: =VLOOKUP(F21,'[1]国标管件 1'!$C:$I,3,FALSE) -> dn110 90Elbow w/Co(PVC-U DF) -LESSO | I21: =_xlfn.DISPIMG("ID_9B50CA48978940CE99789BC2AF98BF88",1) -> =DISPIMG("ID_9B50CA48978940CE99789BC2AF98BF88",1) | J21: =D21 -> 个 | K21: =E21 -> 2 | L21: 联塑 | M21: =VLOOKUP(F21,'[1]国标管件 1'!$C:$I,7,FALSE) -> 25180 | N21: =M21*K21 -> 50360 | O21: 现货
A22: 15 | B22: 排水管 | C22: 45度弯头 | D22: 个 | E22: 16 | F22: 8020020556 | G22: =VLOOKUP(F22,'[1]国标管件 1'!$C:$I,2,FALSE) -> 45°弯头PVC-U排水配件白色 dn110 | H22: =VLOOKUP(F22,'[1]国标管件 1'!$C:$I,3,FALSE) -> 45° Elbow (PVC-U DF) dn110 - LESSO | I22: dn110 | J22: =D22 -> 个 | K22: =E22 -> 16 | L22: 联塑 | M22: =VLOOKUP(F22,'[1]国标管件 1'!$C:$I,7,FALSE) -> 14562 | N22: =M22*K22 -> 232992 | O22: 现货
A23: 16 | B23: 排水管 | C23: 100变50三通 | D23: 个 | E23: 10 | F23: 8020020430 | G23: 90°异径三通PVC-U排水配件白色 dn110×50 | H23: =VLOOKUP(F23,'[1]国标管件 1'!$C:$I,3,FALSE) -> Reducing Tee Drainage PVC-U dn110×50 - LESSO | I23: dn110×50 | J23: 个 | K23: =E23 -> 10 | L23: 联塑 | M23: =VLOOKUP(F23,'[1]国标管件 1'!$C:$I,7,FALSE) -> 16142 | N23: =M23*K23 -> 161420 | O23: 现货
A24: 17 | B24: 排水管 | C24: 100变50直通 | D24: 个 | E24: 10 | F24: 8020020047 | G24: 大小头PVC-U排水配件白色 dn110×50 | H24: =VLOOKUP(F24,'[1]国标管件 1'!$C:$I,3,FALSE) -> Reducer 110mm x 50mm - LESSO | I24: dn110×50 | J24: 个 | K24: =E24 -> 10 | L24: 联塑 | M24: =VLOOKUP(F24,'[1]国标管件 1'!$C:$I,7,FALSE) -> 6277 | N24: =M24*K24 -> 62770 | O24: 现货
A25: 18 | B25: 排水管 | C25: 50正三通 | D25: 个 | E25: 10 | F25: 8020020343 | G25: 90°顺水三通(等径三通)PVC-U排水配件白色 dn50 | H25: =VLOOKUP(F25,'[1]国标管件 1'!$C:$I,3,FALSE) -> dn50 Sanitary tee(PVC-U DF) -LESSO | I25: dn50 | J25: 个 | K25: =E25 -> 10 | L25: 联塑 | M25: =VLOOKUP(F25,'[1]国标管件 1'!$C:$I,7,FALSE) -> 3905 | N25: =M25*K25 -> 39050 | O25: 现货
A26: 19 | B26: 排水管 | C26: 分两片管卡 | D26: 个 | E26: 20 | F26: 8020020186 | G26: =VLOOKUP(F26,'[1]国标管件 1'!$C:$I,2,FALSE) -> Ⅲ型管卡PVC-U排水配件白色 dn110 | H26: =VLOOKUP(F26,'[1]国标管件 1'!$C:$I,3,FALSE) -> dn110 Pipe clamp(T|PVC-U DF) -LESSO | I26: =_xlfn.DISPIMG("ID_A795FFADFCFE45248E1BDD65B948AE2F",1) -> =DISPIMG("ID_A795FFADFCFE45248E1BDD65B948AE2F",1) | J26: =D26 -> 个 | K26: =E26 -> 20 | L26: 联塑 | M26: =VLOOKUP(F26,'[1]国标管件 1'!$C:$I,7,FALSE) -> 8722 | N26: =M26*K26 -> 174440 | O26: 现货
A27: 20 | B27: 排水管 | C27: 直通 | D27: 个 | E27: 6 | F27: 8020020756 | G27: =VLOOKUP(F27,'[1]国标管件 1'!$C:$I,2,FALSE) -> 直通(管)PVC-U排水配件白色dn75 | H27: =VLOOKUP(F27,'[1]国标管件 1'!$C:$I,3,FALSE) -> Coupling PVC-U Drainage Fittings White dn75 - LESSO | I27: dn75 | J27: =D27 -> 个 | K27: =E27 -> 6 | L27: 联塑 | M27: =VLOOKUP(F27,'[1]国标管件 1'!$C:$I,7,FALSE) -> 4200 | N27: =M27*K27 -> 25200 | O27: 现货
A28: 21 | B28: 排水管 | C28: 50 | D28: 根 | E28: 6 | F28: 8020010109 | G28: =VLOOKUP(F28,'[1]国标管件 1'!$C:$I,2,FALSE) -> 建筑排水用PVC-U管(A)白色 dn50 4M | H28: =VLOOKUP(F28,'[1]国标管件 1'!$C:$I,3,FALSE) -> Drain Pipe PVC-U (A) dn50 4M - LESSO | I28: dn50 | J28: 4M/根 | K28: =E28 -> 6 | L28: 联塑 | M28: =VLOOKUP(F28,'[1]国标管件 1'!$C:$I,7,FALSE) -> 46875 | N28: =M28*K28 -> 281250 | O28: 现货
A29: 22 | B29: 排水管 | C29: 存水弯，带检修盖50 | D29: 个 | E29: 15 | F29: 8020020266 | G29: =VLOOKUP(F29,'[1]国标管件 1'!$C:$I,2,FALSE) -> 存水弯(带检查口)PVC-U排水配件白色 dn50 | H29: =VLOOKUP(F29,'[1]国标管件 1'!$C:$I,3,FALSE) -> Trap With Cleanout (PVC-U DF) dn50 - LESSO | I29: =_xlfn.DISPIMG("ID_9BBD092970FF48ABAA27E100FD34BE68",1) -> =DISPIMG("ID_9BBD092970FF48ABAA27E100FD34BE68",1) | J29: =D29 -> 个 | K29: =E29 -> 15 | L29: 联塑 | M29: =VLOOKUP(F29,'[1]国标管件 1'!$C:$I,7,FALSE) -> 4717 | N29: =M29*K29 -> 70755 | O29: 现货
A30: 23 | B30: 排水管 | C30: 50斜三通 | D30: 个 | E30: 5 | F30: 8020020410 | G30: =VLOOKUP(F30,'[1]国标管件 1'!$C:$I,2,FALSE) -> 45°斜三通PVC-U排水配件白色 dn50 | H30: =VLOOKUP(F30,'[1]国标管件 1'!$C:$I,3,FALSE) -> dn50 Wye(PVC-U DF) -LESSO | I30: dn50 | J30: =D30 -> 个 | K30: =E30 -> 5 | L30: 联塑 | M30: =VLOOKUP(F30,'[1]国标管件 1'!$C:$I,7,FALSE) -> 5184 | N30: =M30*K30 -> 25920 | O30: 现货
A31: 24 | B31: 排水管 | C31: 50正三通 | D31: 个 | E31: 10 | F31: 8020020343 | G31: =VLOOKUP(F31,'[1]国标管件 1'!$C:$I,2,FALSE) -> 90°顺水三通(等径三通)PVC-U排水配件白色 dn50 | H31: =VLOOKUP(F31,'[1]国标管件 1'!$C:$I,3,FALSE) -> dn50 Sanitary tee(PVC-U DF) -LESSO | I31: dn50 | J31: =D31 -> 个 | K31: =E31 -> 10 | L31: 联塑 | M31: =VLOOKUP(F31,'[1]国标管件 1'!$C:$I,7,FALSE) -> 3905 | N31: =M31*K31 -> 39050 | O31: 现货
A32: 25 | B32: 排水管 | C32: 50直通 | D32: 个 | E32: 10 | F32: 无货
A33: 26 | B33: 排水管 | C33: 90度弯头 | D33: 个 | E33: 10 | F33: 8020020597 | G33: =VLOOKUP(F33,'[1]国标管件 1'!$C:$I,2,FALSE) -> 90°直角弯头PVC-U排水配件白色 dn50 | H33: =VLOOKUP(F33,'[1]国标管件 1'!$C:$I,3,FALSE) -> elbow dia 90 50mm - LESSO | I33: dn50 | J33: =D33 -> 个 | K33: =E33 -> 10 | L33: 联塑 | M33: =VLOOKUP(F33,'[1]国标管件 1'!$C:$I,7,FALSE) -> 3230 | N33: =M33*K33 -> 32300 | O33: 现货
A34: 27 | B34: 排水管 | C34: 45度弯头 | D34: 个 | E34: 20 | F34: 8020020563 | G34: =VLOOKUP(F34,'[1]国标管件 1'!$C:$I,2,FALSE) -> 45°弯头PVC-U排水配件白色 dn50 | H34: =VLOOKUP(F34,'[1]国标管件 1'!$C:$I,3,FALSE) -> 45° Elbow (PVC-U DF) dn50 - LESSO | I34: dn50 | J34: =D34 -> 个 | K34: =E34 -> 20 | L34: 联塑 | M34: =VLOOKUP(F34,'[1]国标管件 1'!$C:$I,7,FALSE) -> 2159 | N34: =M34*K34 -> 43180 | O34: 现货
A35: 28 | B35: 排水管 | C35: 分两片管卡 | D35: 个 | E35: 16 | F35: 8020020187 | G35: =VLOOKUP(F35,'[1]国标管件 1'!$C:$I,2,FALSE) -> Ⅲ型管卡PVC-U排水配件白色 dn50 | H35: =VLOOKUP(F35,'[1]国标管件 1'!$C:$I,3,FALSE) -> dn50 Pipe clamp(T|PVC-U DF) -LESSO | I35: =_xlfn.DISPIMG("ID_41FA737B82EC4BCB811485D56B043164",1) -> =DISPIMG("ID_41FA737B82EC4BCB811485D56B043164",1) | J35: =D35 -> 个 | K35: =E35 -> 16 | L35: 联塑 | M35: =VLOOKUP(F35,'[1]国标管件 1'!$C:$I,7,FALSE) -> 4307 | N35: =M35*K35 -> 68912 | O35: 现货
A36: 29 | B36: 排水管 | C36: 50U型管卡 | D36: 个 | E36: 10 | F36: 无货
A37: 30 | B37: ppr | C37: 50变40直通 | D37: 个 | E37: 1 | F37: 8010071454 | G37: =VLOOKUP(F37,[1]LESSO管材!$C:$L,2,FALSE) -> 异径套(PPR 配件)印尼绿色 dn50x40 (1-1/2"x1-1/4") 联塑 | H37: =VLOOKUP(F37,[1]LESSO管材!$C:$L,3,FALSE) -> PPR Reducer dn50x40 (1-1/2"x1-1/4") Green(INA) - LESSO | I37: dn50x40 | J37: 个 | K37: 1 | L37: 联塑 | M37: =VLOOKUP(F37,[1]LESSO管材!$C:$L,10,FALSE) -> 8290 | N37: =M37*K37 -> 8290 | O37: 现货
A38: 31 | B38: PPR管 | C38: 40 | D38: 根 | E38: 5 | F38: 8010062268 | G38: =VLOOKUP(F38,[1]LESSO管材!$C:$L,2,FALSE) -> (IDN)PPR冷给水直管S5(1.0MPa)印尼绿色 dn40 (1-1/4") 4M/根 联塑 | H38: =VLOOKUP(F38,[1]LESSO管材!$C:$L,3,FALSE) -> (IDN)PPR Pipe S5(1.0Mpa) dn40 (1-1/4") 4M/pcs Green(INA) - LESSO | I38: dn40 | J38: 4M/根 | K38: =E38 -> 5 | L38: 联塑 | M38: =VLOOKUP(F38,[1]LESSO管材!$C:$L,10,FALSE) -> 66142 | N38: =M38*K38 -> 330710 | O38: 现货
A39: 32 | B39: PPR管 | C39: 直通 | D39: 个 | E39: 10 | F39: 8010071380 | G39: =VLOOKUP(F39,[1]LESSO管材!$C:$L,2,FALSE) -> 直通(PPR 配件)印尼绿色 dn40 (1-1/4") 联塑 | H39: =VLOOKUP(F39,[1]LESSO管材!$C:$L,3,FALSE) -> PPR Coupling dn40 (1-1/4")- LESSO | I39: dn40 | J39: =D39 -> 个 | K39: =E39 -> 10 | L39: 联塑 | M39: =VLOOKUP(F39,[1]LESSO管材!$C:$L,10,FALSE) -> 4514 | N39: =M39*K39 -> 45140 | O39: 现货
A40: 33 | B40: PPR管 | C40: 45度弯头 | D40: 个 | E40: 4 | F40: 8010071438 | G40: =VLOOKUP(F40,[1]LESSO管材!$C:$L,2,FALSE) -> 45°弯头(PPR 配件)印尼绿色 dn40 (1-1/4") 联塑 | H40: =VLOOKUP(F40,[1]LESSO管材!$C:$L,3,FALSE) -> PPR 45° Elbow dn40 (1-1/4") Green(INA) - LESSO | I40: dn40 | J40: =D40 -> 个 | K40: =E40 -> 4 | L40: 联塑 | M40: =VLOOKUP(F40,[1]LESSO管材!$C:$L,10,FALSE) -> 6720 | N40: =M40*K40 -> 26880 | O40: 现货
A41: 34 | B41: PPR管 | C41: 90度弯头 | D41: 个 | E41: 10 | F41: 8010071404 | G41: =VLOOKUP(F41,[1]LESSO管材!$C:$L,2,FALSE) -> 90°弯头(PPR 配件)印尼绿色 dn40 (1-1/4") 联塑 | H41: =VLOOKUP(F41,[1]LESSO管材!$C:$L,3,FALSE) -> PPR 90° Elbow dn40 (1-1/4") Green(INA) - LESSO | I41: dn40 | J41: =D41 -> 个 | K41: =E41 -> 10 | L41: 联塑 | M41: =VLOOKUP(F41,[1]LESSO管材!$C:$L,10,FALSE) -> 7456 | N41: =M41*K41 -> 74560 | O41: 现货
...
